<?xml version="1.0"?>
<!-- This URDF was automatically created by SolidWorks to URDF Exporter! Originally created by Stephen Brawner (brawner@gmail.com) 
     Commit Version: 1.6.0-4-g7f85cfe  Build Version: 1.6.7995.38578
     For more information, please see http://wiki.ros.org/sw_urdf_exporter -->
<robot
  name="fruit_vehicle_arm" xmlns:xacro="http://ros.org/wiki/xacro">
  # Add this before base link
  <link name="dummy_link"></link>
  <link
    name="base_chassis_link">
    <inertial>
      <origin
        xyz="0.087017 -0.254 0.15167"
        rpy="0 0 0" />
      <mass
        value="158.88" />
      <inertia
        ixx="2.7645"
        ixy="1.3635E-16"
        ixz="0.14718"
        iyy="9.7347"
        iyz="-4.0246E-07"
        izz="11.716" />
    </inertial>
    <visual>
      <origin
        xyz="0 0 0"
        rpy="0 0 0" />
      <geometry>
        <mesh
          filename="package://fruit_vehicle_arm/meshes/base_chassis_link.STL" />
      </geometry>
      <material
        name="">
        <color
          rgba="1 0.647 0 1" />
      </material>
    </visual>
    <collision>
      <origin
        xyz="0 0 0"
        rpy="0 0 0" />
      <geometry>
        <mesh
          filename="package://fruit_vehicle_arm/meshes/base_chassis_link.STL" />
      </geometry>
    </collision>
  </link>
  # Add this after base link
  <joint name="dummy_joint" type="fixed">
      <origin rpy="0 0 0" xyz="0 0 0" />
      <parent link="dummy_link"/>
      <child link="base_chassis_link"/>
  </joint>
  <link
    name="rear_left_wheel_link">
    <inertial>
      <origin
        xyz="-4.9826570758249E-08 -6.00333797673436E-08 -9.363213336816E-05"
        rpy="0 0 0" />
      <mass
        value="0.784079252834122" />
      <inertia
        ixx="0.00313877186753156"
        ixy="1.13845295642848E-08"
        ixz="3.73865756301693E-09"
        iyy="0.00313877014381181"
        iyz="3.0127620523046E-09"
        izz="0.00532754482672668" />
    </inertial>
    <visual>
      <origin
        xyz="0 0 0"
        rpy="0 0 0" />
      <geometry>
        <mesh
          filename="package://fruit_vehicle_arm/meshes/rear_left_wheel_link.STL" />
      </geometry>
      <material
        name="">
        <color
          rgba="0 0 0 1" />
      </material>
    </visual>
    <collision>
      <origin
        xyz="0 0 0"
        rpy="0 0 0" />
      <geometry>
        <mesh
          filename="package://fruit_vehicle_arm/meshes/rear_left_wheel_link.STL" />
      </geometry>
    </collision>
  </link>
  <joint
    name="rear_left_wheel_joint"
    type="continuous">
    <origin
      xyz="0 0 0.1016"
      rpy="1.5708 0 0" />
    <parent
      link="base_chassis_link" />
    <child
      link="rear_left_wheel_link" />
    <axis
      xyz="0 0 -1" />
    <limit
      effort="30"
      velocity="6" />
    <dynamics damping="0.1" friction="0.05" /> <!-- Fine-tune these values -->
  </joint>
  <link
    name="rear_right_wheel_link">
    <inertial>
      <origin
        xyz="-7.25355550623696E-08 -2.94789358479264E-08 9.36317316124827E-05"
        rpy="0 0 0" />
      <mass
        value="0.784079220999344" />
      <inertia
        ixx="0.00313877685784208"
        ixy="9.80107157547172E-09"
        ixz="-4.00030025684517E-09"
        iyy="0.0031387651464266"
        iyz="-2.65238154905891E-09"
        izz="0.00532754482329061" />
    </inertial>
    <visual>
      <origin
        xyz="0 0 0"
        rpy="0 0 0" />
      <geometry>
        <mesh
          filename="package://fruit_vehicle_arm/meshes/rear_right_wheel_link.STL" />
      </geometry>
      <material
        name="">
        <color
          rgba="0 0 0 1" />
      </material>
    </visual>
    <collision>
      <origin
        xyz="0 0 0"
        rpy="0 0 0" />
      <geometry>
        <mesh
          filename="package://fruit_vehicle_arm/meshes/rear_right_wheel_link.STL" />
      </geometry>
    </collision>
  </link>
  <joint
    name="rear_right_wheel_joint"
    type="continuous">
    <origin
      xyz="0 -0.508000000000002 0.101600000000001"
      rpy="1.5707963267949 0 0" />
    <parent
      link="base_chassis_link" />
    <child
      link="rear_right_wheel_link" />
    <axis
      xyz="0 0 1" />
    <limit
      effort="30"
      velocity="6" />
    <dynamics damping="0.1" friction="0.05" /> <!-- Fine-tune these values -->
  </joint>
  <link
    name="front_left_wheel_revolute_link">
    <inertial>
      <origin
        xyz="1.22124532708767E-15 0.0441998322829882 -0.042510111403507"
        rpy="0 0 0" />
      <mass
        value="0.200576881049191" />
      <inertia
        ixx="0.000369683498051665"
        ixy="-1.1118705425367E-18"
        ixz="2.32830724824954E-19"
        iyy="5.18373707811601E-05"
        iyz="6.64392826806987E-05"
        izz="0.000332287662706047" />
    </inertial>
    <visual>
      <origin
        xyz="0 0 0"
        rpy="0 0 0" />
      <geometry>
        <mesh
          filename="package://fruit_vehicle_arm/meshes/front_left_wheel_revolute_link.STL" />
      </geometry>
      <material
        name="">
        <color
          rgba="0.898039215686275 0.917647058823529 0.929411764705882 1" />
      </material>
    </visual>
    <collision>
      <origin
        xyz="0 0 0"
        rpy="0 0 0" />
      <geometry>
        <mesh
          filename="package://fruit_vehicle_arm/meshes/front_left_wheel_revolute_link.STL" />
      </geometry>
    </collision>
  </link>
  <joint
    name="front_left_wheel_revolute_joint"
    type="revolute">
    <origin
      xyz="0.508000000000001 -0.120650000000001 0.151600000000001"
      rpy="0 0 0" />
    <parent
      link="base_chassis_link" />
    <child
      link="front_left_wheel_revolute_link" />
    <axis
      xyz="0 0 -1" />
    <limit
      lower="-0.26"
      upper="0.26"
      effort="0"
      velocity="0" />
    <safety_controller
      soft_upper_limit="0.66"
      soft_lower_limit="-0.26"
      k_velocity="0" />
    <dynamics damping="0.1" friction="0.05" /> <!-- Fine-tune these values -->
  </joint>
  <link
    name="front_left_wheel_link">
    <inertial>
      <origin
        xyz="-2.56660644959439E-08 7.39707209373996E-08 -9.36317316134749E-05"
        rpy="0 0 0" />
      <mass
        value="0.784079220999348" />
      <inertia
        ixx="0.00313876052101589"
        ixy="-4.52730308330953E-09"
        ixz="6.43639447255339E-10"
        iyy="0.0031387814832528"
        iyz="-4.75639131493849E-09"
        izz="0.00532754482329061" />
    </inertial>
    <visual>
      <origin
        xyz="0 0 0"
        rpy="0 0 0" />
      <geometry>
        <mesh
          filename="package://fruit_vehicle_arm/meshes/front_left_wheel_link.STL" />
      </geometry>
      <material
        name="">
        <color
          rgba="0 0 0 1" />
      </material>
    </visual>
    <collision>
      <origin
        xyz="0 0 0"
        rpy="0 0 0" />
      <geometry>
        <mesh
          filename="package://fruit_vehicle_arm/meshes/front_left_wheel_link.STL" />
      </geometry>
    </collision>
  </link>
  <joint
    name="front_left_wheel_joint"
    type="continuous">
    <origin
      xyz="0 0.120704104017929 -0.05"
      rpy="1.5707963267949 0 0" />
    <parent
      link="front_left_wheel_revolute_link" />
    <child
      link="front_left_wheel_link" />
    <axis
      xyz="0 0 -1" />
    <limit
      effort="30"
      velocity="6" />
    <dynamics damping="0.1" friction="0.05" /> <!-- Fine-tune these values -->
  </joint>
  <link
    name="front_right_wheel_revolute_link">
    <inertial>
      <origin
        xyz="1.66533453693773E-15 -0.0441998322829901 -0.0425101114035069"
        rpy="0 0 0" />
      <mass
        value="0.200576881049191" />
      <inertia
        ixx="0.000369683498051665"
        ixy="-1.78997664883668E-19"
        ixz="-6.01526521430622E-20"
        iyy="5.183737078116E-05"
        iyz="-6.64392826806986E-05"
        izz="0.000332287662706047" />
    </inertial>
    <visual>
      <origin
        xyz="0 0 0"
        rpy="0 0 0" />
      <geometry>
        <mesh
          filename="package://fruit_vehicle_arm/meshes/front_right_wheel_revolute_link.STL" />
      </geometry>
      <material
        name="">
        <color
          rgba="0.898039215686275 0.917647058823529 0.929411764705882 1" />
      </material>
    </visual>
    <collision>
      <origin
        xyz="0 0 0"
        rpy="0 0 0" />
      <geometry>
        <mesh
          filename="package://fruit_vehicle_arm/meshes/front_right_wheel_revolute_link.STL" />
      </geometry>
    </collision>
  </link>
  <joint
    name="front_right_wheel_revolute_joint"
    type="revolute">
    <origin
      xyz="0.507999999999999 -0.387350000000003 0.151600000000001"
      rpy="0 0 0" />
    <parent
      link="base_chassis_link" />
    <child
      link="front_right_wheel_revolute_link" />
    <axis
      xyz="0 0 -1" />
    <limit
      lower="-0.66"
      upper="0.26"
      effort="0"
      velocity="0" />
    <safety_controller
      soft_upper_limit="0.243"
      soft_lower_limit="-0.603"
      k_position="100"
      k_velocity="0" />
    <dynamics damping="0.1" friction="0.05" /> <!-- Fine-tune these values -->
  </joint>
  <link
    name="front_right_wheel_link">
    <inertial>
      <origin
        xyz="-7.68976589071713E-08 1.47364999092403E-08 9.36317316134472E-05"
        rpy="0 0 0" />
      <mass
        value="0.784079220999348" />
      <inertia
        ixx="0.00313878233921512"
        ixy="-1.34941354711019E-09"
        ixz="-4.79949634266107E-09"
        iyy="0.00313875966505358"
        iyz="-4.86308110983573E-11"
        izz="0.00532754482329062" />
    </inertial>
    <visual>
      <origin
        xyz="0 0 0"
        rpy="0 0 0" />
      <geometry>
        <mesh
          filename="package://fruit_vehicle_arm/meshes/front_right_wheel_link.STL" />
      </geometry>
      <material
        name="">
        <color
          rgba="0 0 0 1" />
      </material>
    </visual>
    <collision>
      <origin
        xyz="0 0 0"
        rpy="0 0 0" />
      <geometry>
        <mesh
          filename="package://fruit_vehicle_arm/meshes/front_right_wheel_link.STL" />
      </geometry>
    </collision>
  </link>
  <joint
    name="front_right_wheel_joint"
    type="continuous">
    <origin
      xyz="0 -0.120704104017928 -0.0499999999999999"
      rpy="1.5707963267949 0 0" />
    <parent
      link="front_right_wheel_revolute_link" />
    <child
      link="front_right_wheel_link" />
    <axis
      xyz="0 0 1" />
    <limit
      effort="30"
      velocity="6" />
    <dynamics damping="0.1" friction="0.05" /> <!-- Fine-tune these values -->
  </joint>
  <link
    name="lidar_mount_link">
    <inertial>
      <origin
        xyz="0 0 0.000253999999999754"
        rpy="0 0 0" />
      <mass
        value="0.114868051974007" />
      <inertia
        ixx="8.37812546680682E-05"
        ixy="-4.08865909427106E-21"
        ixz="1.1000784671411E-21"
        iyy="8.37812546680683E-05"
        iyz="4.07333050851227E-22"
        izz="0.000142380518370692" />
    </inertial>
    <visual>
      <origin
        xyz="0 0 0"
        rpy="0 0 0" />
      <geometry>
        <mesh
          filename="package://fruit_vehicle_arm/meshes/lidar_mount_link.STL" />
      </geometry>
      <material
        name="">
        <color
          rgba="0.498039215686275 0.498039215686275 0.498039215686275 1" />
      </material>
    </visual>
    <collision>
      <origin
        xyz="0 0 0"
        rpy="0 0 0" />
      <geometry>
        <mesh
          filename="package://fruit_vehicle_arm/meshes/lidar_mount_link.STL" />
      </geometry>
    </collision>
  </link>
  <joint
    name="lidar_mount_fixed_joint"
    type="fixed">
    <origin
      xyz="0.0976723407068822 -0.254000000000001 0.469100000000001"
      rpy="0 0 0" />
    <parent
      link="base_chassis_link" />
    <child
      link="lidar_mount_link" />
    <axis
      xyz="0 0 0" />
  </joint>
  <link
    name="basket_link">
    <inertial>
      <origin
        xyz="-1.66533453693773E-16 3.33066907387547E-16 0.0275088248198601"
        rpy="0 0 0" />
      <mass
        value="7.85757316254919" />
      <inertia
        ixx="0.0459267563628034"
        ixy="-1.06459187748712E-17"
        ixz="-3.24460139062564E-16"
        iyy="0.111496373975222"
        iyz="2.01766765517888E-16"
        izz="0.140832289993602" />
    </inertial>
    <visual>
      <origin
        xyz="0 0 0"
        rpy="0 0 0" />
      <geometry>
        <mesh
          filename="package://fruit_vehicle_arm/meshes/basket_link.STL" />
      </geometry>
      <material
        name="">
        <color
          rgba="1 1 1 1" />
      </material>
    </visual>
    <collision>
      <origin
        xyz="0 0 0"
        rpy="0 0 0" />
      <geometry>
        <mesh
          filename="package://fruit_vehicle_arm/meshes/basket_link.STL" />
      </geometry>
    </collision>
  </link>
  <joint
    name="basket_joint"
    type="fixed">
    <origin
      xyz="-0.200659999999999 -0.187452000000002 0.157950000000001"
      rpy="0 0 0" />
    <parent
      link="base_chassis_link" />
    <child
      link="basket_link" />
    <axis
      xyz="0 0 0" />
  </joint>
  <link
    name="arm_base_link">
    <inertial>
      <origin
        xyz="2.498E-16 1.3878E-17 0.070329"
        rpy="0 0 0" />
      <mass
        value="6.2159" />
      <inertia
        ixx="0.02003"
        ixy="-1.2326E-32"
        ixz="-1.4914E-17"
        iyy="0.02003"
        iyz="-8.8681E-20"
        izz="0.015758" />
    </inertial>
    <visual>
      <origin
        xyz="0 0 0.2320"
        rpy="1.5707 0 0" />
      <geometry>
        <mesh
          filename="package://fruit_vehicle_arm/meshes/arm_base_link.STL" />
      </geometry>
      <material
        name="">
        <color
          rgba="0 0 0 1" />
      </material>
    </visual>
    <collision>
      <origin
        xyz="0 0 0.2320"
        rpy="1.5707 0 0" />
      <geometry>
        <mesh
          filename="package://fruit_vehicle_arm/meshes/arm_base_link.STL" />
      </geometry>
    </collision>
  </link>
  <joint
    name="arm_base_joint"
    type="fixed">
    <origin
      xyz="-0.254746654079698 -0.371000000000001 0.151600000000001"
      rpy="0 0 0" />
    <parent
      link="base_chassis_link" />
    <child
      link="arm_base_link" />
    <axis
      xyz="0 0 0" />
  </joint>
  <link
    name="arm_link1">
    <inertial>
      <origin
        xyz="3.1919E-16 -2.7756E-17 0.081638"
        rpy="0 0 0" />
      <mass
        value="2.1185" />
      <inertia
        ixx="0.0038718"
        ixy="-9.5442E-18"
        ixz="-4.3126E-18"
        iyy="0.0045447"
        iyz="-4.0846E-19"
        izz="0.0026681" />
    </inertial>
    <visual>
      <origin
        xyz="0 0 0.12"
        rpy="1.5707 0 1.5707" />
      <geometry>
        <mesh
          filename="package://fruit_vehicle_arm/meshes/arm_link1.STL" />
      </geometry>
      <material
        name="">
        <color
          rgba="1 0.647 0 1" />
      </material>
    </visual>
    <collision>
      <origin
        xyz="0 0 0.12"
        rpy="1.5707 0 1.5707" />
      <geometry>
        <mesh
          filename="package://fruit_vehicle_arm/meshes/arm_link1.STL" />
      </geometry>
    </collision>
  </link>
  <joint
    name="arm_link1_joint"
    type="revolute">
    <origin
      xyz="0 0 0.1143"
      rpy="0 0 0" />
    <parent
      link="arm_base_link" />
    <child
      link="arm_link1" />
    <axis
      xyz="0 0 1" />
    <limit
      lower="0"
      upper="4.7124"
      effort="50"
      velocity="2" />
    <dynamics damping="0.5" friction="0.3" /> <!-- Fine-tune these values -->
  </joint>
  <link
    name="arm_link2">
    <inertial>
      <origin
        xyz="-2.7756E-17 0.0762 4.1633E-17"
        rpy="0 0 0" />
      <mass
        value="1.8076" />
      <inertia
        ixx="0.010484"
        ixy="9.6463E-19"
        ixz="-4.6648E-17"
        iyy="0.0060188"
        iyz="2.7269E-19"
        izz="0.0059518" />
    </inertial>
    <visual>
      <origin
        xyz="0 0 0"
        rpy="0 0 0" />
      <geometry>
        <mesh
          filename="package://fruit_vehicle_arm/meshes/arm_link2.STL" />
      </geometry>
      <material
        name="">
        <color
          rgba="0 0 0 1" />
      </material>
    </visual>
    <collision>
      <origin
        xyz="0 0 0"
        rpy="0 0 0" />
      <geometry>
        <mesh
          filename="package://fruit_vehicle_arm/meshes/arm_link2.STL" />
      </geometry>
    </collision>
  </link>
  <joint
    name="arm_link2_joint"
    type="revolute">
    <origin
      xyz="0 0 0.11811"
      rpy="1.5708 0 -1.5708" />
    <parent
      link="arm_link1" />
    <child
      link="arm_link2" />
    <axis
      xyz="0 0 -1" />
    <limit
      lower="-1.4"
      upper="1.74"
      effort="70"
      velocity="1.5" />
    <dynamics damping="0.8" friction="0.4" /> <!-- Fine-tune these values -->
  </joint>
  <link
    name="arm_link3">
    <inertial>
      <origin
        xyz="-3.3307E-16 0.059453 -6.1062E-16"
        rpy="0 0 0" />
      <mass
        value="2.9342" />
      <inertia
        ixx="0.013293"
        ixy="6.9848E-17"
        ixz="-8.2327E-18"
        iyy="0.0038252"
        iyz="8.4028E-17"
        izz="0.012096" />
    </inertial>
    <visual>
      <origin
        xyz="0.38 -0.18 -0.054"
        rpy="0 1.5707 -3.14159" />
      <geometry>
        <mesh
          filename="package://fruit_vehicle_arm/meshes/arm_link3.STL" />
      </geometry>
      <material
        name="">
        <color
          rgba="1 0.647 0 1" />
      </material>
    </visual>
    <collision>
      <origin
        xyz="0.38 -0.18 -0.054"
        rpy="0 1.5707 -3.14159" />
      <geometry>
        <mesh
          filename="package://fruit_vehicle_arm/meshes/arm_link3.STL" />
      </geometry>
    </collision>
  </link>
  <joint
    name="arm_link3_joint"
    type="revolute">
    <origin
      xyz="0 0.1524 0"
      rpy="0 0 -1.5708" />
    <parent
      link="arm_link2" />
    <child
      link="arm_link3" />
    <axis
      xyz="0 0 1" />
    <limit
      lower="-0.3"
      upper="2.84"
      effort="50"
      velocity="2.5" />
    <dynamics damping="0.6" friction="0.2" /> <!-- Fine-tune these values -->
  </joint>
  <link
    name="arm_link4">
    <inertial>
      <origin
        xyz="-0.00066954 0 1.3878E-17"
        rpy="0 0 0" />
      <mass
        value="0.46003" />
      <inertia
        ixx="0.00020844"
        ixy="-6.1881E-19"
        ixz="1.4649E-18"
        iyy="0.00026376"
        iyz="-5.6032E-20"
        izz="0.0003527" />
    </inertial>
    <visual>
      <origin
        xyz="-0.332 -0.3825 -0.054"
        rpy="0 1.5707 1.5707" />
      <geometry>
        <mesh
          filename="package://fruit_vehicle_arm/meshes/arm_link4.STL" />
      </geometry>
      <material
        name="">
        <color
          rgba="0 0 0 1" />
      </material>
    </visual>
    <!-- <collision>
      <origin
        xyz="-0.332 -0.3825 -0.054"
        rpy="0 1.5707 1.5707" />
      <geometry>
        <mesh
          filename="package://fruit_vehicle_arm/meshes/arm_link4.STL" />
      </geometry>
    </collision> -->
  </link>
  <joint
    name="arm_link4_joint"
    type="revolute">
    <origin
      xyz="0 0.1524 0"
      rpy="0 0 1.5708" />
    <parent
      link="arm_link3" />
    <child
      link="arm_link4" />
    <axis
      xyz="0 0 1" />
    <limit
      lower="-1.5708"
      upper="1.5708"
      effort="20"
      velocity="3" />
    <dynamics damping="0.3" friction="0.1" /> <!-- Fine-tune these values -->
  </joint>
  <link
    name="gripper_link">
    <inertial>
      <origin
        xyz="0.039428 5.5027E-10 -1.4847E-09"
        rpy="0 0 0" />
      <mass
        value="0.074412" />
      <inertia
        ixx="6.8029E-05"
        ixy="2.0608E-12"
        ixz="-5.5603E-12"
        iyy="5.7489E-05"
        iyz="-4.3049E-19"
        izz="5.7489E-05" />
    </inertial>
    <visual>
      <origin
        xyz="-0.36 0.048 -0.38"
        rpy="0 0 1.5707" />
      <geometry>
        <mesh
          filename="package://fruit_vehicle_arm/meshes/gripper_link.STL" />
      </geometry>
      <material
        name="">
        <color
          rgba="1 1 1 1" />
      </material>
    </visual>
    <!-- <collision>
      <origin 
        xyz="-0.36 0.048 -0.38"
        rpy="0 0 1.5707" />
      <geometry>
        <mesh
          filename="package://fruit_vehicle_arm/meshes/gripper_link.STL" />
      </geometry>
    </collision> -->
  </link>
  <joint
    name="gripper_joint"
    type="revolute">
    <origin
      xyz="0.0254 0 0"
      rpy="0 0 0" />
    <parent
      link="arm_link4" />
    <child
      link="gripper_link" />
    <axis
      xyz="0 0 1" />
    <limit
      lower="-1.5708"
      upper="1.5708"
      effort="20"
      velocity="3" />
    <dynamics damping="0.3" friction="0.1" /> <!-- Fine-tune these values -->
  </joint>


  <!-- Gazebo-specific link properties  robot arm-->
  <gazebo reference="arm_base_link">
    <material>Gazebo/Black</material>
    <turnGravityOff>true</turnGravityOff>
    <minDepth>0.003</minDepth>
    <!-- Reduce Velocity After Contact-->
    <maxVel>0</maxVel>
  </gazebo>
  <gazebo reference="arm_link1">
    <material>Gazebo/Orange</material>
    <turnGravityOff>true</turnGravityOff>
    <minDepth>0.003</minDepth>
    <maxVel>0</maxVel>
  </gazebo>
  <gazebo reference="arm_link2">
    <material>Gazebo/Black</material>
    <turnGravityOff>true</turnGravityOff>
    <minDepth>0.003</minDepth>
    <maxVel>0</maxVel>
  </gazebo>
  <gazebo reference="arm_link3">
    <material>Gazebo/Orange</material>
    <turnGravityOff>true</turnGravityOff>
    <minDepth>0.003</minDepth>
    <maxVel>0</maxVel>
  </gazebo>
  <gazebo reference="arm_link4">
    <material>Gazebo/Black</material>
    <turnGravityOff>true</turnGravityOff>
    <minDepth>0.003</minDepth>
    <maxVel>0</maxVel>
  </gazebo>
  <gazebo reference="gripper_link">
    <material>Gazebo/White</material>
    <turnGravityOff>true</turnGravityOff>
    <!--Modify Friction-->
    <mu1>10</mu1>
    <mu2>10</mu2>
    <minDepth>0.003</minDepth>
    <maxVel>0</maxVel>
  </gazebo>

  <!-- Gazebo-specific link properties vehicle -->
  <gazebo reference="base_chassis_link">
    <material>Gazebo/Orange</material>
    <minDepth>0.003</minDepth>
    <maxVel>0</maxVel>
  </gazebo>
  <gazebo reference="rear_left_wheel_link">
    <material>Gazebo/Black</material>
    <minDepth>0.003</minDepth>
    <maxVel>0</maxVel>
  </gazebo>
  <gazebo reference="rear_right_wheel_link">
    <material>Gazebo/Black</material>
    <minDepth>0.003</minDepth>
    <maxVel>0</maxVel>
  </gazebo>
  <gazebo reference="front_left_wheel_revolute_link">
    <material>Gazebo/Gray</material>
    <minDepth>0.003</minDepth>
    <maxVel>0</maxVel>
  </gazebo>
  <gazebo reference="front_right_wheel_revolute_link">
    <material>Gazebo/Gray</material>
    <minDepth>0.003</minDepth>
    <maxVel>0</maxVel>
  </gazebo>
  <gazebo reference="front_left_wheel_link">
    <material>Gazebo/Black</material>
    <minDepth>0.003</minDepth>
    <maxVel>0</maxVel>
  </gazebo>
  <gazebo reference="front_right_wheel_link">
    <material>Gazebo/Black</material>
    <minDepth>0.003</minDepth>
    <maxVel>0</maxVel>
  </gazebo>
  <gazebo reference="lidar_mount_link">
    <material>Gazebo/LightGray</material>
    <minDepth>0.003</minDepth>
    <maxVel>0</maxVel>
  </gazebo>
  <gazebo reference="basket_link">
    <material>Gazebo/DarkGray</material>
    <minDepth>0.003</minDepth>
    <maxVel>0</maxVel>
  </gazebo>

 <ros2_control name="GazeboSystem" type="system">
    <hardware>
        <plugin>gazebo_ros2_control/GazeboSystem</plugin>
    </hardware>
  <!-- Velocity Controllers -->

  <joint name="rear_right_wheel_joint">
      <command_interface name="velocity">
          <param name="min">-1000.0</param>
          <param name="max">1000.0</param>
      </command_interface>
      <state_interface name="position"/>
      <state_interface name="velocity"/>
  </joint>

  <joint name="rear_left_wheel_joint">
      <command_interface name="velocity">
          <param name="min">-1000.0</param>
          <param name="max">1000.0</param>
      </command_interface>
      <state_interface name="position"/>
      <state_interface name="velocity"/>
  </joint>


  <!-- Position Controller -->
  <joint name="front_left_wheel_revolute_joint">
      <command_interface name="position">
          <param name="min">-3.14</param>
          <param name="max">3.14</param>
      </command_interface>
      <state_interface name="position"/>
      <state_interface name="velocity"/>
  </joint>

  <joint name="front_right_wheel_revolute_joint">
      <command_interface name="position">
          <param name="min">-3.14</param>
          <param name="max">3.14</param>
      </command_interface>
      <state_interface name="position"/>
      <state_interface name="velocity"/>
  </joint>  

  <joint name="arm_link1_joint">
      <command_interface name="position">
          <param name="min">-3.14</param>
          <param name="max">3.14</param>
      </command_interface>
      <state_interface name="position"/>
      <state_interface name="velocity"/>
  </joint>

  <joint name="arm_link2_joint">
      <command_interface name="position">
          <param name="min">-1.57</param>
          <param name="max">1.57</param>
      </command_interface>
      <state_interface name="position"/>
      <state_interface name="velocity"/>
  </joint>

  <joint name="arm_link3_joint">
      <command_interface name="position">
          <param name="min">-1.0</param>
          <param name="max">4.5</param>
      </command_interface>
      <state_interface name="position"/>
      <state_interface name="velocity"/>
  </joint>

  <joint name="arm_link4_joint">
      <command_interface name="position">
          <param name="min">-2.5</param>
          <param name="max">2.5</param>
      </command_interface>
      <state_interface name="position"/>
      <state_interface name="velocity"/>
  </joint>
  </ros2_control>

  <gazebo>
    <plugin filename="libgazebo_ros2_control.so" name="gazebo_ros2_control">
        <parameters>$(find fruit_vehicle_arm)/config/control.yaml</parameters>
    </plugin>
  </gazebo>

  <gazebo reference="lidar_mount_link">
    <sensor name="lidar" type="ray">
      <pose>0.0 0.0 0.0 0 0 0</pose>
      <always_on>true</always_on>
      <visualize>true</visualize>
      <update_rate>5</update_rate>
      <ray>
        <scan>
          <horizontal>
            <samples>360</samples>
            <resolution>1.00000</resolution>
            <min_angle>0.000000</min_angle>
            <max_angle>6.280000</max_angle>
          </horizontal>
        </scan>
        <range>
          <min>0.120000</min>
          <max>3.5</max>
          <resolution>0.015000</resolution>
        </range>
        <noise>
          <type>gaussian</type>
          <mean>0.0</mean>
          <stddev>0.01</stddev>
        </noise>
      </ray>
      <plugin name="scan" filename="libgazebo_ros_ray_sensor.so">
        <ros>
          <remapping>~/out:=scan</remapping>
        </ros>
        <output_type>sensor_msgs/LaserScan</output_type>
        <frame_name>lidar_mount_link</frame_name>
      </plugin>
    </sensor>
  </gazebo>

  <gazebo reference="base_chassis_link">
    <gravity>true</gravity>
    <sensor name="imu_sensor" type="imu">
      <always_on>true</always_on>
      <update_rate>100</update_rate>
      <visualize>true</visualize>
      <topic>__default_topic__</topic>
      <plugin filename="libgazebo_ros_imu_sensor.so" name="imu_plugin">
        <topicName>imu</topicName>
        <bodyName>base_chassis_link</bodyName>
        <updateRateHZ>10.0</updateRateHZ>
        <gaussianNoise>0.0</gaussianNoise>
        <xyzOffset>0 0 0</xyzOffset>
        <rpyOffset>0 0 0</rpyOffset>
        <frameName>base_chassis_link</frameName>
        <initialOrientationAsReference>false</initialOrientationAsReference>
      </plugin>
      <pose>0 0 0 0 0 0</pose>
    </sensor>
  </gazebo>

  <gazebo>
    <plugin filename="libodometry_plugin.so" name="odometry_plugin">
        <!-- Name of the link for which the odometry is required -->
        <frame>dummy_link</frame>
        <!-- Any arbitray name for the world frame -->
        <world_frame>map</world_frame>
    </plugin>
  </gazebo>


  <!-- Adding gripper plugin-->
  <gazebo>
    <plugin name='vacuum_gripper' filename='libgazebo_ros_vacuum_gripper.so'>

      <!-- This part can be commented out if not required -->
      <ros>

        <!-- Add a namespace -->

        <namespace>/demo</namespace>

        <!-- Remapping service and topic names -->
        <remapping>switch:=custom_switch</remapping>
        <remapping>grasping:=custom_grasping</remapping>
      </ros>

      <!-- Link associated with gripper -->
      <link_name>gripper_link</link_name>

      <!-- Max distance to attract entities -->
      <max_distance>0.2</max_distance>

      <!-- List of entities to be not attracted by the gripper -->
      <fixed>ground_plane</fixed>
      <fixed>wall</fixed>
      <fixed>sun</fixed>
      <fixed>tree_body_1</fixed>
      <fixed>tree_body_0</fixed>

    </plugin>
  </gazebo>

</robot>